<?xml version="1.0"?>
<robot name="room610-audio_shelf-0-robot"
       xmlns:xi="http://www.w3.org/2001/XInclude"
       >
  <gazebo>
    <static>false</static>
  </gazebo>
  <link name="ROOT_link">
    <visual>
      <origin xyz="0 0 0" rpy="0 -0 0"/>
      <geometry>
        <mesh filename="model://room610-audio_shelf-0/meshes/ROOT_link_mesh.dae" scale="1 1 1" />
      </geometry>
    </visual>
    <collision>
      <origin xyz="0 0 0" rpy="0 -0 0"/>
      <geometry>
        <mesh filename="model://room610-audio_shelf-0/meshes/ROOT_link_mesh.dae" scale="1 1 1" />
      </geometry>
    </collision>
    <inertial>
      <mass value="0.001" />
      <origin xyz="0 0 0" rpy="0 -0 0"/>
      <inertia ixx="1e-03" ixy="0" ixz="0" iyy="1e-03" iyz="0" izz="1e-03"/>
    </inertial>
  </link>
  <gazebo reference="ROOT_link">
    <mu1>0.9</mu1>
    <mu2>0.9</mu2>
  </gazebo>
  <link name="AUDIO_SHELF-BODYSET2_link">
    <visual>
      <origin xyz="0.222 0.195 0.08" rpy="0 -0 0"/>
      <geometry>
        <mesh filename="model://room610-audio_shelf-0/meshes/AUDIO_SHELF-BODYSET2_link_mesh.dae" scale="1 1 1" />
      </geometry>
    </visual>
    <collision>
      <origin xyz="0.222 0.195 0.08" rpy="0 -0 0"/>
      <geometry>
        <mesh filename="model://room610-audio_shelf-0/meshes/AUDIO_SHELF-BODYSET2_link_mesh.dae" scale="1 1 1" />
      </geometry>
    </collision>
    <inertial>
      <mass value="0.001" />
      <origin xyz="0 0 0" rpy="0 -0 0"/>
      <inertia ixx="1e-03" ixy="0" ixz="0" iyy="1e-03" iyz="0" izz="1e-03"/>
    </inertial>
  </link>
  <gazebo reference="AUDIO_SHELF-BODYSET2_link">
    <mu1>0.9</mu1>
    <mu2>0.9</mu2>
  </gazebo>
  <link name="AUDIO_SHELF-BODYSET3_link">
    <visual>
      <origin xyz="0.222 -0.565 0.08" rpy="0 -0 0"/>
      <geometry>
        <mesh filename="model://room610-audio_shelf-0/meshes/AUDIO_SHELF-BODYSET3_link_mesh.dae" scale="1 1 1" />
      </geometry>
    </visual>
    <collision>
      <origin xyz="0.222 -0.565 0.08" rpy="0 -0 0"/>
      <geometry>
        <mesh filename="model://room610-audio_shelf-0/meshes/AUDIO_SHELF-BODYSET3_link_mesh.dae" scale="1 1 1" />
      </geometry>
    </collision>
    <inertial>
      <mass value="0.001" />
      <origin xyz="0 0 0" rpy="0 -0 0"/>
      <inertia ixx="1e-03" ixy="0" ixz="0" iyy="1e-03" iyz="0" izz="1e-03"/>
    </inertial>
  </link>
  <gazebo reference="AUDIO_SHELF-BODYSET3_link">
    <mu1>0.9</mu1>
    <mu2>0.9</mu2>
  </gazebo>
  <link name="AUDIO_SHELF-BODYSET6_link">
    <visual>
      <origin xyz="0 0.39 0.18" rpy="0 -0 0"/>
      <geometry>
        <mesh filename="model://room610-audio_shelf-0/meshes/AUDIO_SHELF-BODYSET6_link_mesh.dae" scale="1 1 1" />
      </geometry>
    </visual>
    <collision>
      <origin xyz="0 0.39 0.18" rpy="0 -0 0"/>
      <geometry>
        <mesh filename="model://room610-audio_shelf-0/meshes/AUDIO_SHELF-BODYSET6_link_mesh.dae" scale="1 1 1" />
      </geometry>
    </collision>
    <inertial>
      <mass value="0.001" />
      <origin xyz="0 0 0" rpy="0 -0 0"/>
      <inertia ixx="1e-03" ixy="0" ixz="0" iyy="1e-03" iyz="0" izz="1e-03"/>
    </inertial>
  </link>
  <gazebo reference="AUDIO_SHELF-BODYSET6_link">
    <mu1>0.9</mu1>
    <mu2>0.9</mu2>
  </gazebo>
  <link name="AUDIO_SHELF-BODYSET5_link">
    <visual>
      <origin xyz="0 0.39 0.37" rpy="0 -0 0"/>
      <geometry>
        <mesh filename="model://room610-audio_shelf-0/meshes/AUDIO_SHELF-BODYSET5_link_mesh.dae" scale="1 1 1" />
      </geometry>
    </visual>
    <collision>
      <origin xyz="0 0.39 0.37" rpy="0 -0 0"/>
      <geometry>
        <mesh filename="model://room610-audio_shelf-0/meshes/AUDIO_SHELF-BODYSET5_link_mesh.dae" scale="1 1 1" />
      </geometry>
    </collision>
    <inertial>
      <mass value="0.001" />
      <origin xyz="0 0 0" rpy="0 -0 0"/>
      <inertia ixx="1e-03" ixy="0" ixz="0" iyy="1e-03" iyz="0" izz="1e-03"/>
    </inertial>
  </link>
  <gazebo reference="AUDIO_SHELF-BODYSET5_link">
    <mu1>0.9</mu1>
    <mu2>0.9</mu2>
  </gazebo>
  <link name="AUDIO_SHELF-BODYSET4_link">
    <visual>
      <origin xyz="0 0.39 0.52" rpy="0 -0 0"/>
      <geometry>
        <mesh filename="model://room610-audio_shelf-0/meshes/AUDIO_SHELF-BODYSET4_link_mesh.dae" scale="1 1 1" />
      </geometry>
    </visual>
    <collision>
      <origin xyz="0 0.39 0.52" rpy="0 -0 0"/>
      <geometry>
        <mesh filename="model://room610-audio_shelf-0/meshes/AUDIO_SHELF-BODYSET4_link_mesh.dae" scale="1 1 1" />
      </geometry>
    </collision>
    <inertial>
      <mass value="0.001" />
      <origin xyz="0 0 0" rpy="0 -0 0"/>
      <inertia ixx="1e-03" ixy="0" ixz="0" iyy="1e-03" iyz="0" izz="1e-03"/>
    </inertial>
  </link>
  <gazebo reference="AUDIO_SHELF-BODYSET4_link">
    <mu1>0.9</mu1>
    <mu2>0.9</mu2>
  </gazebo>
  <joint name="DOOR-LEFT" type="revolute">
    <parent link="ROOT_link"/>
    <child  link="AUDIO_SHELF-BODYSET2_link"/>
    <origin xyz="0.222 0.195 0.08" rpy="0 -0 0 "/>
    <axis   xyz="0 0 1"/>
    <limit lower="0" upper="1.5708" effort="100" velocity="0.5" />
    <dynamics damping="0.2" friction="0" />
  </joint>
  <transmission type="pr2_mechanism_model/SimpleTransmission" name="DOOR-LEFT_trans" >
    <actuator name="DOOR-LEFT_motor" />
    <joint name="DOOR-LEFT" />
    <mechanicalReduction>1</mechanicalReduction>
  </transmission>
  <gazebo reference="DOOR-LEFT">
    <cfmDamping>0.4</cfmDamping>
  </gazebo>
  <joint name="DOOR-RIGHT" type="revolute">
    <parent link="ROOT_link"/>
    <child  link="AUDIO_SHELF-BODYSET3_link"/>
    <origin xyz="0.222 -0.565 0.08" rpy="0 -0 0 "/>
    <axis   xyz="0 0 -1"/>
    <limit lower="0" upper="1.5708" effort="100" velocity="0.5" />
    <dynamics damping="0.2" friction="0" />
  </joint>
  <transmission type="pr2_mechanism_model/SimpleTransmission" name="DOOR-RIGHT_trans" >
    <actuator name="DOOR-RIGHT_motor" />
    <joint name="DOOR-RIGHT" />
    <mechanicalReduction>1</mechanicalReduction>
  </transmission>
  <gazebo reference="DOOR-RIGHT">
    <cfmDamping>0.4</cfmDamping>
  </gazebo>
  <joint name="DRAWER1" type="prismatic">
    <parent link="ROOT_link"/>
    <child  link="AUDIO_SHELF-BODYSET6_link"/>
    <origin xyz="0 0.39 0.18" rpy="0 -0 0 "/>
    <axis   xyz="1 0 0"/>
    <limit lower="0" upper="0.465" effort="100" velocity="0.01" />
    <dynamics damping="0.2" friction="0" />
  </joint>
  <transmission type="pr2_mechanism_model/SimpleTransmission" name="DRAWER1_trans" >
    <actuator name="DRAWER1_motor" />
    <joint name="DRAWER1" />
    <mechanicalReduction>1</mechanicalReduction>
  </transmission>
  <gazebo reference="DRAWER1">
    <cfmDamping>0.4</cfmDamping>
  </gazebo>
  <joint name="DRAWER2" type="prismatic">
    <parent link="ROOT_link"/>
    <child  link="AUDIO_SHELF-BODYSET5_link"/>
    <origin xyz="0 0.39 0.37" rpy="0 -0 0 "/>
    <axis   xyz="1 0 0"/>
    <limit lower="0" upper="0.465" effort="100" velocity="0.01" />
    <dynamics damping="0.2" friction="0" />
  </joint>
  <transmission type="pr2_mechanism_model/SimpleTransmission" name="DRAWER2_trans" >
    <actuator name="DRAWER2_motor" />
    <joint name="DRAWER2" />
    <mechanicalReduction>1</mechanicalReduction>
  </transmission>
  <gazebo reference="DRAWER2">
    <cfmDamping>0.4</cfmDamping>
  </gazebo>
  <joint name="DRAWER3" type="prismatic">
    <parent link="ROOT_link"/>
    <child  link="AUDIO_SHELF-BODYSET4_link"/>
    <origin xyz="0 0.39 0.52" rpy="0 -0 0 "/>
    <axis   xyz="1 0 0"/>
    <limit lower="0" upper="0.465" effort="100" velocity="0.01" />
    <dynamics damping="0.2" friction="0" />
  </joint>
  <transmission type="pr2_mechanism_model/SimpleTransmission" name="DRAWER3_trans" >
    <actuator name="DRAWER3_motor" />
    <joint name="DRAWER3" />
    <mechanicalReduction>1</mechanicalReduction>
  </transmission>
  <gazebo reference="DRAWER3">
    <cfmDamping>0.4</cfmDamping>
  </gazebo>
</robot>
