<?xml version="1.0"?>
<robot name="room610-fridge-1-robot_fixed"
       xmlns:xi="http://www.w3.org/2001/XInclude"
       >
  <gazebo>
    <static>false</static>
  </gazebo>
  <link name="ROOT_link">
    <visual>
      <origin xyz="0 0 0" rpy="0 -0 0"/>
      <geometry>
        <mesh filename="model://room610-fridge-1/meshes/ROOT_link_mesh.dae" scale="1 1 1" />
      </geometry>
    </visual>
    <collision>
      <origin xyz="0 0 0" rpy="0 -0 0"/>
      <geometry>
        <mesh filename="model://room610-fridge-1/meshes/ROOT_link_mesh.dae" scale="1 1 1" />
      </geometry>
    </collision>
    <inertial>
      <mass value="0.001" />
      <origin xyz="0 0 0" rpy="0 -0 0"/>
      <inertia ixx="1e-03" ixy="0" ixz="0" iyy="1e-03" iyz="0" izz="1e-03"/>
    </inertial>
  </link>
  <gazebo reference="ROOT_link">
    <mu1>0.9</mu1>
    <mu2>0.9</mu2>
  </gazebo>
  <link name="FRIDGE-BODYSET7_link">
    <visual>
      <origin xyz="0.319 0.317 1" rpy="0 -0 0"/>
      <geometry>
        <mesh filename="model://room610-fridge-1/meshes/FRIDGE-BODYSET7_link_mesh.dae" scale="1 1 1" />
      </geometry>
    </visual>
    <collision>
      <origin xyz="0.319 0.317 1" rpy="0 -0 0"/>
      <geometry>
        <mesh filename="model://room610-fridge-1/meshes/FRIDGE-BODYSET7_link_mesh.dae" scale="1 1 1" />
      </geometry>
    </collision>
    <inertial>
      <mass value="0.001" />
      <origin xyz="0 0 0" rpy="0 -0 0"/>
      <inertia ixx="1e-03" ixy="0" ixz="0" iyy="1e-03" iyz="0" izz="1e-03"/>
    </inertial>
  </link>
  <gazebo reference="FRIDGE-BODYSET7_link">
    <mu1>0.9</mu1>
    <mu2>0.9</mu2>
  </gazebo>
  <link name="FRIDGE-BODYSET6_link">
    <visual>
      <origin xyz="0.319 -0.317 1" rpy="0 -0 0"/>
      <geometry>
        <mesh filename="model://room610-fridge-1/meshes/FRIDGE-BODYSET6_link_mesh.dae" scale="1 1 1" />
      </geometry>
    </visual>
    <collision>
      <origin xyz="0.319 -0.317 1" rpy="0 -0 0"/>
      <geometry>
        <mesh filename="model://room610-fridge-1/meshes/FRIDGE-BODYSET6_link_mesh.dae" scale="1 1 1" />
      </geometry>
    </collision>
    <inertial>
      <mass value="0.001" />
      <origin xyz="0 0 0" rpy="0 -0 0"/>
      <inertia ixx="1e-03" ixy="0" ixz="0" iyy="1e-03" iyz="0" izz="1e-03"/>
    </inertial>
  </link>
  <gazebo reference="FRIDGE-BODYSET6_link">
    <mu1>0.9</mu1>
    <mu2>0.9</mu2>
  </gazebo>
  <link name="FRIDGE-BODYSET3_link">
    <visual>
      <origin xyz="0 0 0.577" rpy="0 -0 0"/>
      <geometry>
        <mesh filename="model://room610-fridge-1/meshes/FRIDGE-BODYSET3_link_mesh.dae" scale="1 1 1" />
      </geometry>
    </visual>
    <collision>
      <origin xyz="0 0 0.577" rpy="0 -0 0"/>
      <geometry>
        <mesh filename="model://room610-fridge-1/meshes/FRIDGE-BODYSET3_link_mesh.dae" scale="1 1 1" />
      </geometry>
    </collision>
    <inertial>
      <mass value="0.001" />
      <origin xyz="0 0 0" rpy="0 -0 0"/>
      <inertia ixx="1e-03" ixy="0" ixz="0" iyy="1e-03" iyz="0" izz="1e-03"/>
    </inertial>
  </link>
  <gazebo reference="FRIDGE-BODYSET3_link">
    <mu1>0.9</mu1>
    <mu2>0.9</mu2>
  </gazebo>
  <link name="FRIDGE-BODYSET2_link">
    <visual>
      <origin xyz="0 0 0.207" rpy="0 -0 0"/>
      <geometry>
        <mesh filename="model://room610-fridge-1/meshes/FRIDGE-BODYSET2_link_mesh.dae" scale="1 1 1" />
      </geometry>
    </visual>
    <collision>
      <origin xyz="0 0 0.207" rpy="0 -0 0"/>
      <geometry>
        <mesh filename="model://room610-fridge-1/meshes/FRIDGE-BODYSET2_link_mesh.dae" scale="1 1 1" />
      </geometry>
    </collision>
    <inertial>
      <mass value="0.001" />
      <origin xyz="0 0 0" rpy="0 -0 0"/>
      <inertia ixx="1e-03" ixy="0" ixz="0" iyy="1e-03" iyz="0" izz="1e-03"/>
    </inertial>
  </link>
  <gazebo reference="FRIDGE-BODYSET2_link">
    <mu1>0.9</mu1>
    <mu2>0.9</mu2>
  </gazebo>
  <link name="FRIDGE-BODYSET4_link">
    <visual>
      <origin xyz="4.54747e-16 0.171 0.867" rpy="0 -0 0"/>
      <geometry>
        <mesh filename="model://room610-fridge-1/meshes/FRIDGE-BODYSET4_link_mesh.dae" scale="1 1 1" />
      </geometry>
    </visual>
    <collision>
      <origin xyz="4.54747e-16 0.171 0.867" rpy="0 -0 0"/>
      <geometry>
        <mesh filename="model://room610-fridge-1/meshes/FRIDGE-BODYSET4_link_mesh.dae" scale="1 1 1" />
      </geometry>
    </collision>
    <inertial>
      <mass value="0.001" />
      <origin xyz="0 0 0" rpy="0 -0 0"/>
      <inertia ixx="1e-03" ixy="0" ixz="0" iyy="1e-03" iyz="0" izz="1e-03"/>
    </inertial>
  </link>
  <gazebo reference="FRIDGE-BODYSET4_link">
    <mu1>0.9</mu1>
    <mu2>0.9</mu2>
  </gazebo>
  <link name="FRIDGE-BODYSET5_link">
    <visual>
      <origin xyz="0 -0.171 0.867" rpy="0 -0 0"/>
      <geometry>
        <mesh filename="model://room610-fridge-1/meshes/FRIDGE-BODYSET5_link_mesh.dae" scale="1 1 1" />
      </geometry>
    </visual>
    <collision>
      <origin xyz="0 -0.171 0.867" rpy="0 -0 0"/>
      <geometry>
        <mesh filename="model://room610-fridge-1/meshes/FRIDGE-BODYSET5_link_mesh.dae" scale="1 1 1" />
      </geometry>
    </collision>
    <inertial>
      <mass value="0.001" />
      <origin xyz="0 0 0" rpy="0 -0 0"/>
      <inertia ixx="1e-03" ixy="0" ixz="0" iyy="1e-03" iyz="0" izz="1e-03"/>
    </inertial>
  </link>
  <gazebo reference="FRIDGE-BODYSET5_link">
    <mu1>0.9</mu1>
    <mu2>0.9</mu2>
  </gazebo>
  <joint name="DOOR-UPPER-LEFT" type="revolute">
    <parent link="ROOT_link"/>
    <child  link="FRIDGE-BODYSET7_link"/>
    <origin xyz="0.319 0.317 1" rpy="0 -0 0 "/>
    <axis   xyz="0 0 1"/>
    <limit lower="0" upper="1.5708" effort="100" velocity="0.5" />
    <dynamics damping="0.2" friction="0" />
  </joint>
  <transmission type="pr2_mechanism_model/SimpleTransmission" name="DOOR-UPPER-LEFT_trans" >
    <actuator name="DOOR-UPPER-LEFT_motor" />
    <joint name="DOOR-UPPER-LEFT" />
    <mechanicalReduction>1</mechanicalReduction>
  </transmission>
  <gazebo reference="DOOR-UPPER-LEFT">
    <cfmDamping>0.4</cfmDamping>
  </gazebo>
  <joint name="DOOR-UPPER-RIGHT" type="revolute">
    <parent link="ROOT_link"/>
    <child  link="FRIDGE-BODYSET6_link"/>
    <origin xyz="0.319 -0.317 1" rpy="0 -0 0 "/>
    <axis   xyz="0 0 -1"/>
    <limit lower="0" upper="1.5708" effort="100" velocity="0.5" />
    <dynamics damping="0.2" friction="0" />
  </joint>
  <transmission type="pr2_mechanism_model/SimpleTransmission" name="DOOR-UPPER-RIGHT_trans" >
    <actuator name="DOOR-UPPER-RIGHT_motor" />
    <joint name="DOOR-UPPER-RIGHT" />
    <mechanicalReduction>1</mechanicalReduction>
  </transmission>
  <gazebo reference="DOOR-UPPER-RIGHT">
    <cfmDamping>0.4</cfmDamping>
  </gazebo>
  <joint name="DRAWER-LOWER1" type="prismatic">
    <parent link="ROOT_link"/>
    <child  link="FRIDGE-BODYSET3_link"/>
    <origin xyz="0 0 0.577" rpy="0 -0 0 "/>
    <axis   xyz="1 0 0"/>
    <limit lower="0" upper="0.688" effort="100" velocity="0.01" />
    <dynamics damping="0.2" friction="0" />
  </joint>
  <transmission type="pr2_mechanism_model/SimpleTransmission" name="DRAWER-LOWER1_trans" >
    <actuator name="DRAWER-LOWER1_motor" />
    <joint name="DRAWER-LOWER1" />
    <mechanicalReduction>1</mechanicalReduction>
  </transmission>
  <gazebo reference="DRAWER-LOWER1">
    <cfmDamping>0.4</cfmDamping>
  </gazebo>
  <joint name="DRAWER-LOWER2" type="prismatic">
    <parent link="ROOT_link"/>
    <child  link="FRIDGE-BODYSET2_link"/>
    <origin xyz="0 0 0.207" rpy="0 -0 0 "/>
    <axis   xyz="1 0 0"/>
    <limit lower="0" upper="0.688" effort="100" velocity="0.01" />
    <dynamics damping="0.2" friction="0" />
  </joint>
  <transmission type="pr2_mechanism_model/SimpleTransmission" name="DRAWER-LOWER2_trans" >
    <actuator name="DRAWER-LOWER2_motor" />
    <joint name="DRAWER-LOWER2" />
    <mechanicalReduction>1</mechanicalReduction>
  </transmission>
  <gazebo reference="DRAWER-LOWER2">
    <cfmDamping>0.4</cfmDamping>
  </gazebo>
  <joint name="DRAWER-MIDDLE-LEFT" type="prismatic">
    <parent link="ROOT_link"/>
    <child  link="FRIDGE-BODYSET4_link"/>
    <origin xyz="4.54747e-16 0.171 0.867" rpy="0 -0 0 "/>
    <axis   xyz="1 0 0"/>
    <limit lower="0" upper="0.688" effort="100" velocity="0.01" />
    <dynamics damping="0.2" friction="0" />
  </joint>
  <transmission type="pr2_mechanism_model/SimpleTransmission" name="DRAWER-MIDDLE-LEFT_trans" >
    <actuator name="DRAWER-MIDDLE-LEFT_motor" />
    <joint name="DRAWER-MIDDLE-LEFT" />
    <mechanicalReduction>1</mechanicalReduction>
  </transmission>
  <gazebo reference="DRAWER-MIDDLE-LEFT">
    <cfmDamping>0.4</cfmDamping>
  </gazebo>
  <joint name="DRAWER-MIDDLE-RIGHT" type="prismatic">
    <parent link="ROOT_link"/>
    <child  link="FRIDGE-BODYSET5_link"/>
    <origin xyz="0 -0.171 0.867" rpy="0 -0 0 "/>
    <axis   xyz="1 0 0"/>
    <limit lower="0" upper="0.688" effort="100" velocity="0.01" />
    <dynamics damping="0.2" friction="0" />
  </joint>
  <transmission type="pr2_mechanism_model/SimpleTransmission" name="DRAWER-MIDDLE-RIGHT_trans" >
    <actuator name="DRAWER-MIDDLE-RIGHT_motor" />
    <joint name="DRAWER-MIDDLE-RIGHT" />
    <mechanicalReduction>1</mechanicalReduction>
  </transmission>
  <gazebo reference="DRAWER-MIDDLE-RIGHT">
    <cfmDamping>0.4</cfmDamping>
  </gazebo>
  <!-- Used for fixing robot to Gazebo 'base_link' -->
  <link name="world"/>
  <joint name="fixed" type="fixed">
    <parent link="world"/>
    <child link="ROOT_link"/>
  </joint>
</robot>
